Workbook
Name Customer_ID: #REF!
Name GaugeHeader: #REF!
Name MekkoHeader: #REF!
Name Month: #REF!
Name OrgChartHeader: #REF!
Name RadialBarChartHeader: #REF!
Name raphic5: #REF!
Name RingHeader: #REF!
Name rngGreenColor: #REF!
Name rngPlanColor: #REF!
Name rngRedColor: #REF!
Name rngWFConnectorsColor: #REF!
Name rngWFGreenColor: #REF!
Name rngWFRedColor: #REF!
Name rngWFStarEndColor: #REF!
Name rngZLColor: #REF!
Name SalesFunnel2Header: #REF!
Name SalesFunnelHeader: #REF!
Name SF2_F: #REF!
Name TrafficLightHeader: #REF!
Name VAH_F1: #REF!
Name VAH_F2: #REF!
Name VarianceActualHorizontalHeader: #REF!
Name VarianceHeader: #REF!
Name WaterFallHeader: #REF!
Name WindRoseHeader: #REF!

Sheet Templates >

Sheet Final demand(2)
B2: Final demand changes (consumption, govt, etc) | H2: CVF_lower | I2: =1/3 -> 0.33333333 | J2: hh
B3: Fields with * must be specified manually or filled in automatically by selecting values in other columns | H3: 2 | I3: =1/3 -> 0.33333333 | J3: gov
B5: Country | C5: Country ISO* | F5: Product | G5: Product code* | H5: Final demand category | I5: FD code* | J5: Type* | K5: Comments
B6: Italy | C6: =_xlfn.IFNA(INDEX('[1]Country list'!$A$2:$A$166,MATCH(B6,'[1]Country list'!$B$2:$B$166,0)),"") -> ITA | F6: ALL | G6: =_xlfn.IFNA(INDEX('[1]Sector list'!$A$2:$A$122,MATCH(F6,'[1]Sector list'!$B$2:$B$122,0)),"") -> ALL | H6: Household final consumption P.3h | I6: =_xlfn.IFNA(INDEX('[1]FD list'!$A$2:$A$122,MATCH(H6,'[1]FD list'!$B$2:$B$122,0)),"") -> FD_1 | J6: rel-b | K6: << Decrease final demand (HH consumption) 3% for all products in Italy
C7: ITA | F7: Pork | G7: =_xlfn.IFNA(INDEX('[1]Sector list'!$A$2:$A$122,MATCH(F7,'[1]Sector list'!$B$2:$B$122,0)),"") -> 43 | H7: ALL | I7: =_xlfn.IFNA(INDEX('[1]FD list'!$A$2:$A$122,MATCH(H7,'[1]FD list'!$B$2:$B$122,0)),"") -> ALL | J7: rel-b | K7: << Increase final demand (across all demand categories) for pork in Italy by 12% (if zero stays zero)
B8: Germany | C8: =_xlfn.IFNA(INDEX('[1]Country list'!$A$2:$A$166,MATCH(B8,'[1]Country list'!$B$2:$B$166,0)),"") -> DEU | G8: 1-23 | I8: FD_1 | J8: abs-b | K8: << Increase demand in Germany for all agricultural sectors (1-23), only for consumer demand; try NOT to use negative values as it might create issues
B9: Malawi | C9: =_xlfn.IFNA(INDEX('[1]Country list'!$A$2:$A$166,MATCH(B9,'[1]Country list'!$B$2:$B$166,0)),"") -> MWI | F9: Building construction | G9: =_xlfn.IFNA(INDEX('[1]Sector list'!$A$2:$A$122,MATCH(F9,'[1]Sector list'!$B$2:$B$122,0)),"") -> 98 | H9: Gross fixed capital formation P.51 | I9: =_xlfn.IFNA(INDEX('[1]FD list'!$A$2:$A$122,MATCH(H9,'[1]FD list'!$B$2:$B$122,0)),"") -> FD_4 | J9: rel-b | K9: << Directly decrease investment (GFCF) demand for construction sector in Malawi with 1%; NOTE: if you want to do INVESTMENT BY the sector IT SHOULD NOT BE DONE HERE
C13: REG_exp | E13: REG_imp | G13: TRAD_COMM | I13: PROD_COMM (only FD) | J13: Current options: rel-b and abs-b
B14: Start in the next line >>
B15: Producing country | C15: Producing country ISO* | D15: Consuming country | E15: Consuming country ISO* | F15: Product | G15: Product code* | H15: Final demand category | I15: FD code* | J15: Type* | K15: Comments | L15: 2019 | M15: 2020 | N15: 2021 | O15: 2022 | P15: 2023 | Q15: 2024 | R15: 2025 | S15: 2026 | T15: 2027 | U15: 2028 | V15: 2029 | W15: 2030 | X15: 2031 | Y15: 2032 | Z15: 2033 | AA15: 2034 | AB15: 2035 | AC15: 2036 | AD15: 2037 | AE15: 2038 | AF15: 2039 | AG15: 2040 | AH15: 2041 | AI15: 2042 | AJ15: 2043 | AK15: 2044 | AL15: 2045 | AM15: 2046 | AN15: 2047 | AO15: 2048 | AP15: 2049 | AQ15: 2050
C16: SEP | E16: SEP | F16: ALL | G16: ALL | H16: Household final consumption P.3h | I16: FD_1 | J16: abs-b | K16: =SUM(X16:AL16)/1000000 -> 0.34262129 | X16: =VLOOKUP($C16,'MSET pivots'!$B$4:$H$14,$H$3,FALSE)*1000000*$I$2*'MSET pivots'!E$65 -> 11420.881 | Y16: =VLOOKUP($C16,'MSET pivots'!$B$4:$H$14,$H$3,FALSE)*1000000*$I2*'MSET pivots'!F$65 -> 13052.386 | Z16: =VLOOKUP($C16,'MSET pivots'!$B$4:$H$14,$H$3,FALSE)*1000000*$I2*'MSET pivots'!G$65 -> 14683.892 | AA16: =VLOOKUP($C16,'MSET pivots'!$B$4:$H$14,$H$3,FALSE)*1000000*$I2*'MSET pivots'!H$65 -> 16315.397 | AB16: =VLOOKUP($C16,'MSET pivots'!$B$4:$H$14,$H$3,FALSE)*1000000*$I2*'MSET pivots'!I$65 -> 17946.903 | AC16: =VLOOKUP($C16,'MSET pivots'!$B$4:$H$14,$H$3,FALSE)*1000000*$I2*'MSET pivots'!J$65 -> 19578.408 | AD16: =VLOOKUP($C16,'MSET pivots'!$B$4:$H$14,$H$3,FALSE)*1000000*$I2*'MSET pivots'!K$65 -> 21209.914 | AE16: =VLOOKUP($C16,'MSET pivots'!$B$4:$H$14,$H$3,FALSE)*1000000*$I2*'MSET pivots'!L$65 -> 22841.419 | AF16: =VLOOKUP($C16,'MSET pivots'!$B$4:$H$14,$H$3,FALSE)*1000000*$I2*'MSET pivots'!M$65 -> 24472.925 | ... AL16: =VLOOKUP($C16,'MSET pivots'!$B$4:$H$14,$H$3,FALSE)*1000000*$I2*'MSET pivots'!S$65 -> 34261.957
C17: SEP | E17: SEP | F17: ALL | G17: ALL | H17: Government final consumption P.3g | I17: FD_3 | J17: abs-b | K17: =SUM(X17:AL17)/1000000 -> 0.34262129 | X17: =VLOOKUP($C17,'MSET pivots'!$B$4:$H$14,$H$3,FALSE)*1000000*$I$3*'MSET pivots'!E$65 -> 11420.881 | Y17: =VLOOKUP($C17,'MSET pivots'!$B$4:$H$14,$H$3,FALSE)*1000000*$I3*'MSET pivots'!F$65 -> 13052.386 | Z17: =VLOOKUP($C17,'MSET pivots'!$B$4:$H$14,$H$3,FALSE)*1000000*$I3*'MSET pivots'!G$65 -> 14683.892 | AA17: =VLOOKUP($C17,'MSET pivots'!$B$4:$H$14,$H$3,FALSE)*1000000*$I3*'MSET pivots'!H$65 -> 16315.397 | AB17: =VLOOKUP($C17,'MSET pivots'!$B$4:$H$14,$H$3,FALSE)*1000000*$I3*'MSET pivots'!I$65 -> 17946.903 | AC17: =VLOOKUP($C17,'MSET pivots'!$B$4:$H$14,$H$3,FALSE)*1000000*$I3*'MSET pivots'!J$65 -> 19578.408 | AD17: =VLOOKUP($C17,'MSET pivots'!$B$4:$H$14,$H$3,FALSE)*1000000*$I3*'MSET pivots'!K$65 -> 21209.914 | AE17: =VLOOKUP($C17,'MSET pivots'!$B$4:$H$14,$H$3,FALSE)*1000000*$I3*'MSET pivots'!L$65 -> 22841.419 | AF17: =VLOOKUP($C17,'MSET pivots'!$B$4:$H$14,$H$3,FALSE)*1000000*$I3*'MSET pivots'!M$65 -> 24472.925 | ... AL17: =VLOOKUP($C17,'MSET pivots'!$B$4:$H$14,$H$3,FALSE)*1000000*$I3*'MSET pivots'!S$65 -> 34261.957
C18: AFR | E18: AFR | F18: ALL | G18: ALL | H18: Household final consumption P.3h | I18: FD_1 | J18: abs-b | K18: =SUM(X18:AL18)/1000000 -> 0.35655058 | X18: =VLOOKUP($C18,'MSET pivots'!$B$4:$H$14,$H$3,FALSE)*1000000*$I$2*'MSET pivots'!E$65 -> 11885.198 | Y18: =VLOOKUP($C18,'MSET pivots'!$B$4:$H$14,$H$3,FALSE)*1000000*$I$2*'MSET pivots'!F$65 -> 13583.032 | Z18: =VLOOKUP($C18,'MSET pivots'!$B$4:$H$14,$H$3,FALSE)*1000000*$I$2*'MSET pivots'!G$65 -> 15280.866 | AA18: =VLOOKUP($C18,'MSET pivots'!$B$4:$H$14,$H$3,FALSE)*1000000*$I$2*'MSET pivots'!H$65 -> 16978.701 | AB18: =VLOOKUP($C18,'MSET pivots'!$B$4:$H$14,$H$3,FALSE)*1000000*$I$2*'MSET pivots'!I$65 -> 18676.535 | AC18: =VLOOKUP($C18,'MSET pivots'!$B$4:$H$14,$H$3,FALSE)*1000000*$I$2*'MSET pivots'!J$65 -> 20374.37 | AD18: =VLOOKUP($C18,'MSET pivots'!$B$4:$H$14,$H$3,FALSE)*1000000*$I$2*'MSET pivots'!K$65 -> 22072.204 | AE18: =VLOOKUP($C18,'MSET pivots'!$B$4:$H$14,$H$3,FALSE)*1000000*$I$2*'MSET pivots'!L$65 -> 23770.039 | ... AL18: =VLOOKUP($C18,'MSET pivots'!$B$4:$H$14,$H$3,FALSE)*1000000*$I$2*'MSET pivots'!S$65 -> 35654.88
C19: AFR | E19: AFR | F19: ALL | G19: ALL | H19: Government final consumption P.3g | I19: FD_3 | J19: abs-b | K19: =SUM(X19:AL19)/1000000 -> 0.35655058 | X19: =VLOOKUP($C19,'MSET pivots'!$B$4:$H$14,$H$3,FALSE)*1000000*$I$3*'MSET pivots'!E$65 -> 11885.198 | Y19: =VLOOKUP($C19,'MSET pivots'!$B$4:$H$14,$H$3,FALSE)*1000000*$I$3*'MSET pivots'!F$65 -> 13583.032 | Z19: =VLOOKUP($C19,'MSET pivots'!$B$4:$H$14,$H$3,FALSE)*1000000*$I$3*'MSET pivots'!G$65 -> 15280.866 | AA19: =VLOOKUP($C19,'MSET pivots'!$B$4:$H$14,$H$3,FALSE)*1000000*$I$3*'MSET pivots'!H$65 -> 16978.701 | AB19: =VLOOKUP($C19,'MSET pivots'!$B$4:$H$14,$H$3,FALSE)*1000000*$I$3*'MSET pivots'!I$65 -> 18676.535 | AC19: =VLOOKUP($C19,'MSET pivots'!$B$4:$H$14,$H$3,FALSE)*1000000*$I$3*'MSET pivots'!J$65 -> 20374.37 | AD19: =VLOOKUP($C19,'MSET pivots'!$B$4:$H$14,$H$3,FALSE)*1000000*$I$3*'MSET pivots'!K$65 -> 22072.204 | AE19: =VLOOKUP($C19,'MSET pivots'!$B$4:$H$14,$H$3,FALSE)*1000000*$I$3*'MSET pivots'!L$65 -> 23770.039 | ... AL19: =VLOOKUP($C19,'MSET pivots'!$B$4:$H$14,$H$3,FALSE)*1000000*$I$3*'MSET pivots'!S$65 -> 35654.88
C20: LAC | E20: LAC | F20: ALL | G20: ALL | H20: Household final consumption P.3h | I20: FD_1 | J20: abs-b | K20: =SUM(X20:AL20)/1000000 -> 0.26441491 | X20: =VLOOKUP($C20,'MSET pivots'!$B$4:$H$14,$H$3,FALSE)*1000000*$I$2*'MSET pivots'!E$65 -> 8813.9627 | Y20: =VLOOKUP($C20,'MSET pivots'!$B$4:$H$14,$H$3,FALSE)*1000000*$I$2*'MSET pivots'!F$65 -> 10073.062 | Z20: =VLOOKUP($C20,'MSET pivots'!$B$4:$H$14,$H$3,FALSE)*1000000*$I$2*'MSET pivots'!G$65 -> 11332.162 | AA20: =VLOOKUP($C20,'MSET pivots'!$B$4:$H$14,$H$3,FALSE)*1000000*$I$2*'MSET pivots'!H$65 -> 12591.262 | AB20: =VLOOKUP($C20,'MSET pivots'!$B$4:$H$14,$H$3,FALSE)*1000000*$I$2*'MSET pivots'!I$65 -> 13850.362 | AC20: =VLOOKUP($C20,'MSET pivots'!$B$4:$H$14,$H$3,FALSE)*1000000*$I$2*'MSET pivots'!J$65 -> 15109.461 | AD20: =VLOOKUP($C20,'MSET pivots'!$B$4:$H$14,$H$3,FALSE)*1000000*$I$2*'MSET pivots'!K$65 -> 16368.561 | AE20: =VLOOKUP($C20,'MSET pivots'!$B$4:$H$14,$H$3,FALSE)*1000000*$I$2*'MSET pivots'!L$65 -> 17627.661 | ... AL20: =VLOOKUP($C20,'MSET pivots'!$B$4:$H$14,$H$3,FALSE)*1000000*$I$2*'MSET pivots'!S$65 -> 26441.359
C21: LAC | E21: LAC | F21: ALL | G21: ALL | H21: Government final consumption P.3g | I21: FD_3 | J21: abs-b | K21: =SUM(X21:AL21)/1000000 -> 0.26441491 | X21: =VLOOKUP($C21,'MSET pivots'!$B$4:$H$14,$H$3,FALSE)*1000000*$I$3*'MSET pivots'!E$65 -> 8813.9627 | Y21: =VLOOKUP($C21,'MSET pivots'!$B$4:$H$14,$H$3,FALSE)*1000000*$I$3*'MSET pivots'!F$65 -> 10073.062 | Z21: =VLOOKUP($C21,'MSET pivots'!$B$4:$H$14,$H$3,FALSE)*1000000*$I$3*'MSET pivots'!G$65 -> 11332.162 | AA21: =VLOOKUP($C21,'MSET pivots'!$B$4:$H$14,$H$3,FALSE)*1000000*$I$3*'MSET pivots'!H$65 -> 12591.262 | AB21: =VLOOKUP($C21,'MSET pivots'!$B$4:$H$14,$H$3,FALSE)*1000000*$I$3*'MSET pivots'!I$65 -> 13850.362 | AC21: =VLOOKUP($C21,'MSET pivots'!$B$4:$H$14,$H$3,FALSE)*1000000*$I$3*'MSET pivots'!J$65 -> 15109.461 | AD21: =VLOOKUP($C21,'MSET pivots'!$B$4:$H$14,$H$3,FALSE)*1000000*$I$3*'MSET pivots'!K$65 -> 16368.561 | AE21: =VLOOKUP($C21,'MSET pivots'!$B$4:$H$14,$H$3,FALSE)*1000000*$I$3*'MSET pivots'!L$65 -> 17627.661 | ... AL21: =VLOOKUP($C21,'MSET pivots'!$B$4:$H$14,$H$3,FALSE)*1000000*$I$3*'MSET pivots'!S$65 -> 26441.359
B22: Pakistan | C22: SAS | E22: SAS | F22: ALL | G22: ALL | H22: Household final consumption P.3h | I22: FD_1 | J22: abs-b | K22: =SUM(X22:AL22)/1000000 -> 0.3297289 | W22: ='Preliminary results'!$C$31*1000000*I2 -> 902060.73 | X22: =VLOOKUP($C22,'MSET pivots'!$B$4:$H$14,$H$3,FALSE)*1000000*$I$2*'MSET pivots'!E$65 -> 10991.128 | Y22: =VLOOKUP($C22,'MSET pivots'!$B$4:$H$14,$H$3,FALSE)*1000000*$I$2*'MSET pivots'!F$65 -> 12561.242 | Z22: =VLOOKUP($C22,'MSET pivots'!$B$4:$H$14,$H$3,FALSE)*1000000*$I$2*'MSET pivots'!G$65 -> 14131.356 | AA22: =VLOOKUP($C22,'MSET pivots'!$B$4:$H$14,$H$3,FALSE)*1000000*$I$2*'MSET pivots'!H$65 -> 15701.47 | AB22: =VLOOKUP($C22,'MSET pivots'!$B$4:$H$14,$H$3,FALSE)*1000000*$I$2*'MSET pivots'!I$65 -> 17271.584 | AC22: =VLOOKUP($C22,'MSET pivots'!$B$4:$H$14,$H$3,FALSE)*1000000*$I$2*'MSET pivots'!J$65 -> 18841.698 | AD22: =VLOOKUP($C22,'MSET pivots'!$B$4:$H$14,$H$3,FALSE)*1000000*$I$2*'MSET pivots'!K$65 -> 20411.813 | AE22: =VLOOKUP($C22,'MSET pivots'!$B$4:$H$14,$H$3,FALSE)*1000000*$I$2*'MSET pivots'!L$65 -> 21981.927 | ... AL22: =VLOOKUP($C22,'MSET pivots'!$B$4:$H$14,$H$3,FALSE)*1000000*$I$2*'MSET pivots'!S$65 -> 32972.725
B23: Pakistan | C23: SAS | E23: SAS | F23: ALL | G23: ALL | H23: Government final consumption P.3g | I23: FD_3 | J23: abs-b | K23: =SUM(X23:AL23)/1000000 -> 0.3297289 | W23: ='Preliminary results'!$C$31*1000000*I3 -> 902060.73 | X23: =VLOOKUP($C23,'MSET pivots'!$B$4:$H$14,$H$3,FALSE)*1000000*$I$3*'MSET pivots'!E$65 -> 10991.128 | Y23: =VLOOKUP($C23,'MSET pivots'!$B$4:$H$14,$H$3,FALSE)*1000000*$I$3*'MSET pivots'!F$65 -> 12561.242 | Z23: =VLOOKUP($C23,'MSET pivots'!$B$4:$H$14,$H$3,FALSE)*1000000*$I$3*'MSET pivots'!G$65 -> 14131.356 | AA23: =VLOOKUP($C23,'MSET pivots'!$B$4:$H$14,$H$3,FALSE)*1000000*$I$3*'MSET pivots'!H$65 -> 15701.47 | AB23: =VLOOKUP($C23,'MSET pivots'!$B$4:$H$14,$H$3,FALSE)*1000000*$I$3*'MSET pivots'!I$65 -> 17271.584 | AC23: =VLOOKUP($C23,'MSET pivots'!$B$4:$H$14,$H$3,FALSE)*1000000*$I$3*'MSET pivots'!J$65 -> 18841.698 | AD23: =VLOOKUP($C23,'MSET pivots'!$B$4:$H$14,$H$3,FALSE)*1000000*$I$3*'MSET pivots'!K$65 -> 20411.813 | AE23: =VLOOKUP($C23,'MSET pivots'!$B$4:$H$14,$H$3,FALSE)*1000000*$I$3*'MSET pivots'!L$65 -> 21981.927 | ... AL23: =VLOOKUP($C23,'MSET pivots'!$B$4:$H$14,$H$3,FALSE)*1000000*$I$3*'MSET pivots'!S$65 -> 32972.725
C24: AJN | E24: AJN | F24: ALL | G24: ALL | H24: Government final consumption P.3g | I24: FD_3 | J24: rel-b | K24: =SUM(X24:AL24) -> -0.00027375815 | X24: =VLOOKUP($C24,'MSET pivots'!$J$4:$P$14,'Final demand(2)'!$H$3,FALSE)*'MSET pivots'!E$65 -> -9.1254086e-06 | Y24: =VLOOKUP($C24,'MSET pivots'!$J$4:$P$14,'Final demand(2)'!$H$3,FALSE)*'MSET pivots'!F$65 -> -1.0428999e-05 | Z24: =VLOOKUP($C24,'MSET pivots'!$J$4:$P$14,'Final demand(2)'!$H$3,FALSE)*'MSET pivots'!G$65 -> -1.173259e-05 | AA24: =VLOOKUP($C24,'MSET pivots'!$J$4:$P$14,'Final demand(2)'!$H$3,FALSE)*'MSET pivots'!H$65 -> -1.3036181e-05 | AB24: =VLOOKUP($C24,'MSET pivots'!$J$4:$P$14,'Final demand(2)'!$H$3,FALSE)*'MSET pivots'!I$65 -> -1.4339771e-05 | AC24: =VLOOKUP($C24,'MSET pivots'!$J$4:$P$14,'Final demand(2)'!$H$3,FALSE)*'MSET pivots'!J$65 -> -1.5643362e-05 | AD24: =VLOOKUP($C24,'MSET pivots'!$J$4:$P$14,'Final demand(2)'!$H$3,FALSE)*'MSET pivots'!K$65 -> -1.6946953e-05 | AE24: =VLOOKUP($C24,'MSET pivots'!$J$4:$P$14,'Final demand(2)'!$H$3,FALSE)*'MSET pivots'!L$65 -> -1.8250543e-05 | ... AL24: =VLOOKUP($C24,'MSET pivots'!$J$4:$P$14,'Final demand(2)'!$H$3,FALSE)*'MSET pivots'!S$65 -> -2.7375678e-05
C25: EAS | E25: EAS | F25: ALL | G25: ALL | H25: Government final consumption P.3g | I25: FD_3 | J25: rel-b | K25: =SUM(X25:AL25) -> -0.0001409855 | X25: =VLOOKUP($C25,'MSET pivots'!$J$4:$P$14,'Final demand(2)'!$H$3,FALSE)*'MSET pivots'!E$65 -> -4.6995871e-06 | Y25: =VLOOKUP($C25,'MSET pivots'!$J$4:$P$14,'Final demand(2)'!$H$3,FALSE)*'MSET pivots'!F$65 -> -5.3709365e-06 | Z25: =VLOOKUP($C25,'MSET pivots'!$J$4:$P$14,'Final demand(2)'!$H$3,FALSE)*'MSET pivots'!G$65 -> -6.042286e-06 | AA25: =VLOOKUP($C25,'MSET pivots'!$J$4:$P$14,'Final demand(2)'!$H$3,FALSE)*'MSET pivots'!H$65 -> -6.7136354e-06 | AB25: =VLOOKUP($C25,'MSET pivots'!$J$4:$P$14,'Final demand(2)'!$H$3,FALSE)*'MSET pivots'!I$65 -> -7.3849848e-06 | AC25: =VLOOKUP($C25,'MSET pivots'!$J$4:$P$14,'Final demand(2)'!$H$3,FALSE)*'MSET pivots'!J$65 -> -8.0563343e-06 | AD25: =VLOOKUP($C25,'MSET pivots'!$J$4:$P$14,'Final demand(2)'!$H$3,FALSE)*'MSET pivots'!K$65 -> -8.7276837e-06 | AE25: =VLOOKUP($C25,'MSET pivots'!$J$4:$P$14,'Final demand(2)'!$H$3,FALSE)*'MSET pivots'!L$65 -> -9.3990332e-06 | ... AL25: =VLOOKUP($C25,'MSET pivots'!$J$4:$P$14,'Final demand(2)'!$H$3,FALSE)*'MSET pivots'!S$65 -> -1.4098479e-05
C26: EEA | E26: EEA | F26: ALL | G26: ALL | H26: Government final consumption P.3g | I26: FD_3 | J26: rel-b | K26: =SUM(X26:AL26) -> -0.00029291557 | X26: =VLOOKUP($C26,'MSET pivots'!$J$4:$P$14,'Final demand(2)'!$H$3,FALSE)*'MSET pivots'!E$65 -> -9.7639988e-06 | Y26: =VLOOKUP($C26,'MSET pivots'!$J$4:$P$14,'Final demand(2)'!$H$3,FALSE)*'MSET pivots'!F$65 -> -1.1158814e-05 | Z26: =VLOOKUP($C26,'MSET pivots'!$J$4:$P$14,'Final demand(2)'!$H$3,FALSE)*'MSET pivots'!G$65 -> -1.2553629e-05 | AA26: =VLOOKUP($C26,'MSET pivots'!$J$4:$P$14,'Final demand(2)'!$H$3,FALSE)*'MSET pivots'!H$65 -> -1.3948444e-05 | AB26: =VLOOKUP($C26,'MSET pivots'!$J$4:$P$14,'Final demand(2)'!$H$3,FALSE)*'MSET pivots'!I$65 -> -1.5343259e-05 | AC26: =VLOOKUP($C26,'MSET pivots'!$J$4:$P$14,'Final demand(2)'!$H$3,FALSE)*'MSET pivots'!J$65 -> -1.6738074e-05 | AD26: =VLOOKUP($C26,'MSET pivots'!$J$4:$P$14,'Final demand(2)'!$H$3,FALSE)*'MSET pivots'!K$65 -> -1.813289e-05 | AE26: =VLOOKUP($C26,'MSET pivots'!$J$4:$P$14,'Final demand(2)'!$H$3,FALSE)*'MSET pivots'!L$65 -> -1.9527705e-05 | ... AL26: =VLOOKUP($C26,'MSET pivots'!$J$4:$P$14,'Final demand(2)'!$H$3,FALSE)*'MSET pivots'!S$65 -> -2.9291411e-05
B27: United Kingdom | C27: EUR | E27: EUR | F27: ALL | G27: ALL | H27: Government final consumption P.3g | I27: FD_3 | J27: rel-b | K27: =SUM(X27:AL27) -> -0.00021328804 | W27: =('Preliminary results'!$C$31)/'Baseline govt spend'!$E$51 -> 0.00066729533 | X27: =VLOOKUP($C27,'MSET pivots'!$J$4:$P$14,'Final demand(2)'!$H$3,FALSE)*'MSET pivots'!E$65 -> -7.109708e-06 | Y27: =VLOOKUP($C27,'MSET pivots'!$J$4:$P$14,'Final demand(2)'!$H$3,FALSE)*'MSET pivots'!F$65 -> -8.1253501e-06 | Z27: =VLOOKUP($C27,'MSET pivots'!$J$4:$P$14,'Final demand(2)'!$H$3,FALSE)*'MSET pivots'!G$65 -> -9.1409922e-06 | AA27: =VLOOKUP($C27,'MSET pivots'!$J$4:$P$14,'Final demand(2)'!$H$3,FALSE)*'MSET pivots'!H$65 -> -1.0156634e-05 | AB27: =VLOOKUP($C27,'MSET pivots'!$J$4:$P$14,'Final demand(2)'!$H$3,FALSE)*'MSET pivots'!I$65 -> -1.1172276e-05 | AC27: =VLOOKUP($C27,'MSET pivots'!$J$4:$P$14,'Final demand(2)'!$H$3,FALSE)*'MSET pivots'!J$65 -> -1.2187918e-05 | AD27: =VLOOKUP($C27,'MSET pivots'!$J$4:$P$14,'Final demand(2)'!$H$3,FALSE)*'MSET pivots'!K$65 -> -1.3203561e-05 | AE27: =VLOOKUP($C27,'MSET pivots'!$J$4:$P$14,'Final demand(2)'!$H$3,FALSE)*'MSET pivots'!L$65 -> -1.4219203e-05 | ... AL27: =VLOOKUP($C27,'MSET pivots'!$J$4:$P$14,'Final demand(2)'!$H$3,FALSE)*'MSET pivots'!S$65 -> -2.1328697e-05
C28: MEN | E28: MEN | F28: ALL | G28: ALL | H28: Government final consumption P.3g | I28: FD_3 | J28: rel-b | K28: =SUM(X28:AL28) -> -7.4304334e-05 | X28: =VLOOKUP($C28,'MSET pivots'!$J$4:$P$14,'Final demand(2)'!$H$3,FALSE)*'MSET pivots'!E$65 -> -2.4768483e-06 | Y28: =VLOOKUP($C28,'MSET pivots'!$J$4:$P$14,'Final demand(2)'!$H$3,FALSE)*'MSET pivots'!F$65 -> -2.8306731e-06 | Z28: =VLOOKUP($C28,'MSET pivots'!$J$4:$P$14,'Final demand(2)'!$H$3,FALSE)*'MSET pivots'!G$65 -> -3.184498e-06 | AA28: =VLOOKUP($C28,'MSET pivots'!$J$4:$P$14,'Final demand(2)'!$H$3,FALSE)*'MSET pivots'!H$65 -> -3.5383228e-06 | AB28: =VLOOKUP($C28,'MSET pivots'!$J$4:$P$14,'Final demand(2)'!$H$3,FALSE)*'MSET pivots'!I$65 -> -3.8921477e-06 | AC28: =VLOOKUP($C28,'MSET pivots'!$J$4:$P$14,'Final demand(2)'!$H$3,FALSE)*'MSET pivots'!J$65 -> -4.2459725e-06 | AD28: =VLOOKUP($C28,'MSET pivots'!$J$4:$P$14,'Final demand(2)'!$H$3,FALSE)*'MSET pivots'!K$65 -> -4.5997974e-06 | AE28: =VLOOKUP($C28,'MSET pivots'!$J$4:$P$14,'Final demand(2)'!$H$3,FALSE)*'MSET pivots'!L$65 -> -4.9536223e-06 | ... AL28: =VLOOKUP($C28,'MSET pivots'!$J$4:$P$14,'Final demand(2)'!$H$3,FALSE)*'MSET pivots'!S$65 -> -7.4303962e-06
C29: NAM | E29: NAM | F29: ALL | G29: ALL | H29: Government final consumption P.3g | I29: FD_3 | J29: rel-b | K29: =SUM(X29:AL29) -> -0.00059204867 | X29: =VLOOKUP($C29,'MSET pivots'!$J$4:$P$14,'Final demand(2)'!$H$3,FALSE)*'MSET pivots'!E$65 -> -1.9735252e-05 | Y29: =VLOOKUP($C29,'MSET pivots'!$J$4:$P$14,'Final demand(2)'!$H$3,FALSE)*'MSET pivots'!F$65 -> -2.2554489e-05 | Z29: =VLOOKUP($C29,'MSET pivots'!$J$4:$P$14,'Final demand(2)'!$H$3,FALSE)*'MSET pivots'!G$65 -> -2.5373726e-05 | AA29: =VLOOKUP($C29,'MSET pivots'!$J$4:$P$14,'Final demand(2)'!$H$3,FALSE)*'MSET pivots'!H$65 -> -2.8192963e-05 | AB29: =VLOOKUP($C29,'MSET pivots'!$J$4:$P$14,'Final demand(2)'!$H$3,FALSE)*'MSET pivots'!I$65 -> -3.10122e-05 | AC29: =VLOOKUP($C29,'MSET pivots'!$J$4:$P$14,'Final demand(2)'!$H$3,FALSE)*'MSET pivots'!J$65 -> -3.3831437e-05 | AD29: =VLOOKUP($C29,'MSET pivots'!$J$4:$P$14,'Final demand(2)'!$H$3,FALSE)*'MSET pivots'!K$65 -> -3.6650674e-05 | AE29: =VLOOKUP($C29,'MSET pivots'!$J$4:$P$14,'Final demand(2)'!$H$3,FALSE)*'MSET pivots'!L$65 -> -3.9469911e-05 | ... AL29: =VLOOKUP($C29,'MSET pivots'!$J$4:$P$14,'Final demand(2)'!$H$3,FALSE)*'MSET pivots'!S$65 -> -5.9204571e-05
G42: =_xlfn.IFNA(INDEX('[1]Sector list'!$A$2:$A$122,MATCH(F42,'[1]Sector list'!$B$2:$B$122,0)),"") | I42: =_xlfn.IFNA(INDEX('[1]FD list'!$A$2:$A$122,MATCH(H42,'[1]FD list'!$B$2:$B$122,0)),"")
G43: =_xlfn.IFNA(INDEX('[1]Sector list'!$A$2:$A$122,MATCH(F43,'[1]Sector list'!$B$2:$B$122,0)),"") | I43: =_xlfn.IFNA(INDEX('[1]FD list'!$A$2:$A$122,MATCH(H43,'[1]FD list'!$B$2:$B$122,0)),"")
G44: =_xlfn.IFNA(INDEX('[1]Sector list'!$A$2:$A$122,MATCH(F44,'[1]Sector list'!$B$2:$B$122,0)),"") | I44: =_xlfn.IFNA(INDEX('[1]FD list'!$A$2:$A$122,MATCH(H44,'[1]FD list'!$B$2:$B$122,0)),"")
G45: =_xlfn.IFNA(INDEX('[1]Sector list'!$A$2:$A$122,MATCH(F45,'[1]Sector list'!$B$2:$B$122,0)),"") | I45: =_xlfn.IFNA(INDEX('[1]FD list'!$A$2:$A$122,MATCH(H45,'[1]FD list'!$B$2:$B$122,0)),"")
G46: =_xlfn.IFNA(INDEX('[1]Sector list'!$A$2:$A$122,MATCH(F46,'[1]Sector list'!$B$2:$B$122,0)),"") | I46: =_xlfn.IFNA(INDEX('[1]FD list'!$A$2:$A$122,MATCH(H46,'[1]FD list'!$B$2:$B$122,0)),"")
G47: =_xlfn.IFNA(INDEX('[1]Sector list'!$A$2:$A$122,MATCH(F47,'[1]Sector list'!$B$2:$B$122,0)),"") | I47: =_xlfn.IFNA(INDEX('[1]FD list'!$A$2:$A$122,MATCH(H47,'[1]FD list'!$B$2:$B$122,0)),"")
G48: =_xlfn.IFNA(INDEX('[1]Sector list'!$A$2:$A$122,MATCH(F48,'[1]Sector list'!$B$2:$B$122,0)),"") | I48: =_xlfn.IFNA(INDEX('[1]FD list'!$A$2:$A$122,MATCH(H48,'[1]FD list'!$B$2:$B$122,0)),"")
G49: =_xlfn.IFNA(INDEX('[1]Sector list'!$A$2:$A$122,MATCH(F49,'[1]Sector list'!$B$2:$B$122,0)),"") | I49: =_xlfn.IFNA(INDEX('[1]FD list'!$A$2:$A$122,MATCH(H49,'[1]FD list'!$B$2:$B$122,0)),"")
G50: =_xlfn.IFNA(INDEX('[1]Sector list'!$A$2:$A$122,MATCH(F50,'[1]Sector list'!$B$2:$B$122,0)),"") | I50: =_xlfn.IFNA(INDEX('[1]FD list'!$A$2:$A$122,MATCH(H50,'[1]FD list'!$B$2:$B$122,0)),"")
G51: =_xlfn.IFNA(INDEX('[1]Sector list'!$A$2:$A$122,MATCH(F51,'[1]Sector list'!$B$2:$B$122,0)),"") | I51: =_xlfn.IFNA(INDEX('[1]FD list'!$A$2:$A$122,MATCH(H51,'[1]FD list'!$B$2:$B$122,0)),"")
G52: =_xlfn.IFNA(INDEX('[1]Sector list'!$A$2:$A$122,MATCH(F52,'[1]Sector list'!$B$2:$B$122,0)),"") | I52: =_xlfn.IFNA(INDEX('[1]FD list'!$A$2:$A$122,MATCH(H52,'[1]FD list'!$B$2:$B$122,0)),"")
G53: =_xlfn.IFNA(INDEX('[1]Sector list'!$A$2:$A$122,MATCH(F53,'[1]Sector list'!$B$2:$B$122,0)),"") | I53: =_xlfn.IFNA(INDEX('[1]FD list'!$A$2:$A$122,MATCH(H53,'[1]FD list'!$B$2:$B$122,0)),"")
... G67: =_xlfn.IFNA(INDEX('[1]Sector list'!$A$2:$A$122,MATCH(F67,'[1]Sector list'!$B$2:$B$122,0)),"") | I67: =_xlfn.IFNA(INDEX('[1]FD list'!$A$2:$A$122,MATCH(H67,'[1]FD list'!$B$2:$B$122,0)),"")
I68: =_xlfn.IFNA(INDEX('[1]FD list'!$A$2:$A$122,MATCH(H68,'[1]FD list'!$B$2:$B$122,0)),"")
I69: =_xlfn.IFNA(INDEX('[1]FD list'!$A$2:$A$122,MATCH(H69,'[1]FD list'!$B$2:$B$122,0)),"")
I70: =_xlfn.IFNA(INDEX('[1]FD list'!$A$2:$A$122,MATCH(H70,'[1]FD list'!$B$2:$B$122,0)),"")
...

Sheet Investment by(2)
B2: Investment BY sector changes | G2: ='Final demand(2)'!H2 -> CVF_lower | H2: ='Final demand(2)'!H3 -> 2
B3: Fields with * must be specified manually or filled in automatically by selecting values in other columns
B5: Country | C5: Country ISO* | D5: Sector investing | E5: Sector investing code* | F5: Type* | G5: Comments
G6: =1/3 -> 0.33333333 | H6: FCF
B8: Germany | C8: =_xlfn.IFNA(INDEX('[2]Country list'!$A$2:$A$166,MATCH(B8,'[2]Country list'!$B$2:$B$166,0)),"") -> DEU | E8: 1-23 | F8: abs | G8: << Increase investment in agricultural sectors in Germany, 1000 kUSD in EVERY sector
G12: relative investment is not possible, because we don’t have an investment baseline right now
C13: REG_imp | E13: PROD_COMM | G13: Current options: abs-b
B14: Start in the next line >>
B15: Country | C15: Country ISO* | D15: Sector investing | E15: Sector investing code* | F15: Type* | G15: Comments | H15: 2019 | I15: 2020 | J15: 2021 | K15: 2022 | L15: 2023 | M15: 2024 | N15: 2025 | O15: 2026 | P15: 2027 | Q15: 2028 | R15: 2029 | S15: 2030 | T15: 2031 | U15: 2032 | V15: 2033 | W15: 2034 | X15: 2035 | Y15: 2036 | Z15: 2037 | AA15: 2038 | AB15: 2039 | AC15: 2040 | AD15: 2041 | AE15: 2042 | AF15: 2043 | AG15: 2044 | AH15: 2045 | AI15: 2046 | AJ15: 2047 | AK15: 2048 | AL15: 2049 | AM15: 2050
C16: SEP | E16: ALL | F16: abs-b | G16: =SUM(T16:AH16)/1000000 -> 0.34262129 | T16: =VLOOKUP($C16,'MSET pivots'!$B$4:$H$14,$H$2,FALSE)*1000000*$G$6*'MSET pivots'!E$65 -> 11420.881 | U16: =VLOOKUP($C16,'MSET pivots'!$B$4:$H$14,$H$2,FALSE)*1000000*$G$6*'MSET pivots'!F$65 -> 13052.386 | V16: =VLOOKUP($C16,'MSET pivots'!$B$4:$H$14,$H$2,FALSE)*1000000*$G$6*'MSET pivots'!G$65 -> 14683.892 | W16: =VLOOKUP($C16,'MSET pivots'!$B$4:$H$14,$H$2,FALSE)*1000000*$G$6*'MSET pivots'!H$65 -> 16315.397 | X16: =VLOOKUP($C16,'MSET pivots'!$B$4:$H$14,$H$2,FALSE)*1000000*$G$6*'MSET pivots'!I$65 -> 17946.903 | Y16: =VLOOKUP($C16,'MSET pivots'!$B$4:$H$14,$H$2,FALSE)*1000000*$G$6*'MSET pivots'!J$65 -> 19578.408 | Z16: =VLOOKUP($C16,'MSET pivots'!$B$4:$H$14,$H$2,FALSE)*1000000*$G$6*'MSET pivots'!K$65 -> 21209.914 | AA16: =VLOOKUP($C16,'MSET pivots'!$B$4:$H$14,$H$2,FALSE)*1000000*$G$6*'MSET pivots'!L$65 -> 22841.419 | ... AH16: =VLOOKUP($C16,'MSET pivots'!$B$4:$H$14,$H$2,FALSE)*1000000*$G$6*'MSET pivots'!S$65 -> 34261.957
C17: AFR | E17: ALL | F17: abs-b | G17: =SUM(T17:AH17)/1000000 -> 0.35655058 | T17: =VLOOKUP($C17,'MSET pivots'!$B$4:$H$14,$H$2,FALSE)*1000000*$G$6*'MSET pivots'!E$65 -> 11885.198 | U17: =VLOOKUP($C17,'MSET pivots'!$B$4:$H$14,$H$2,FALSE)*1000000*$G$6*'MSET pivots'!F$65 -> 13583.032 | V17: =VLOOKUP($C17,'MSET pivots'!$B$4:$H$14,$H$2,FALSE)*1000000*$G$6*'MSET pivots'!G$65 -> 15280.866 | W17: =VLOOKUP($C17,'MSET pivots'!$B$4:$H$14,$H$2,FALSE)*1000000*$G$6*'MSET pivots'!H$65 -> 16978.701 | X17: =VLOOKUP($C17,'MSET pivots'!$B$4:$H$14,$H$2,FALSE)*1000000*$G$6*'MSET pivots'!I$65 -> 18676.535 | Y17: =VLOOKUP($C17,'MSET pivots'!$B$4:$H$14,$H$2,FALSE)*1000000*$G$6*'MSET pivots'!J$65 -> 20374.37 | Z17: =VLOOKUP($C17,'MSET pivots'!$B$4:$H$14,$H$2,FALSE)*1000000*$G$6*'MSET pivots'!K$65 -> 22072.204 | AA17: =VLOOKUP($C17,'MSET pivots'!$B$4:$H$14,$H$2,FALSE)*1000000*$G$6*'MSET pivots'!L$65 -> 23770.039 | ... AH17: =VLOOKUP($C17,'MSET pivots'!$B$4:$H$14,$H$2,FALSE)*1000000*$G$6*'MSET pivots'!S$65 -> 35654.88
C18: LAC | E18: ALL | F18: abs-b | G18: =SUM(T18:AH18)/1000000 -> 0.26441491 | T18: =VLOOKUP($C18,'MSET pivots'!$B$4:$H$14,$H$2,FALSE)*1000000*$G$6*'MSET pivots'!E$65 -> 8813.9627 | U18: =VLOOKUP($C18,'MSET pivots'!$B$4:$H$14,$H$2,FALSE)*1000000*$G$6*'MSET pivots'!F$65 -> 10073.062 | V18: =VLOOKUP($C18,'MSET pivots'!$B$4:$H$14,$H$2,FALSE)*1000000*$G$6*'MSET pivots'!G$65 -> 11332.162 | W18: =VLOOKUP($C18,'MSET pivots'!$B$4:$H$14,$H$2,FALSE)*1000000*$G$6*'MSET pivots'!H$65 -> 12591.262 | X18: =VLOOKUP($C18,'MSET pivots'!$B$4:$H$14,$H$2,FALSE)*1000000*$G$6*'MSET pivots'!I$65 -> 13850.362 | Y18: =VLOOKUP($C18,'MSET pivots'!$B$4:$H$14,$H$2,FALSE)*1000000*$G$6*'MSET pivots'!J$65 -> 15109.461 | Z18: =VLOOKUP($C18,'MSET pivots'!$B$4:$H$14,$H$2,FALSE)*1000000*$G$6*'MSET pivots'!K$65 -> 16368.561 | AA18: =VLOOKUP($C18,'MSET pivots'!$B$4:$H$14,$H$2,FALSE)*1000000*$G$6*'MSET pivots'!L$65 -> 17627.661 | ... AH18: =VLOOKUP($C18,'MSET pivots'!$B$4:$H$14,$H$2,FALSE)*1000000*$G$6*'MSET pivots'!S$65 -> 26441.359
C19: SAS | E19: ALL | F19: abs-b | G19: =SUM(T19:AH19)/1000000 -> 0.3297289 | S19: ='Preliminary results'!$C$31*1000000*G6 -> 902060.73 | T19: =VLOOKUP($C19,'MSET pivots'!$B$4:$H$14,$H$2,FALSE)*1000000*$G$6*'MSET pivots'!E$65 -> 10991.128 | U19: =VLOOKUP($C19,'MSET pivots'!$B$4:$H$14,$H$2,FALSE)*1000000*$G$6*'MSET pivots'!F$65 -> 12561.242 | V19: =VLOOKUP($C19,'MSET pivots'!$B$4:$H$14,$H$2,FALSE)*1000000*$G$6*'MSET pivots'!G$65 -> 14131.356 | W19: =VLOOKUP($C19,'MSET pivots'!$B$4:$H$14,$H$2,FALSE)*1000000*$G$6*'MSET pivots'!H$65 -> 15701.47 | X19: =VLOOKUP($C19,'MSET pivots'!$B$4:$H$14,$H$2,FALSE)*1000000*$G$6*'MSET pivots'!I$65 -> 17271.584 | Y19: =VLOOKUP($C19,'MSET pivots'!$B$4:$H$14,$H$2,FALSE)*1000000*$G$6*'MSET pivots'!J$65 -> 18841.698 | Z19: =VLOOKUP($C19,'MSET pivots'!$B$4:$H$14,$H$2,FALSE)*1000000*$G$6*'MSET pivots'!K$65 -> 20411.813 | AA19: =VLOOKUP($C19,'MSET pivots'!$B$4:$H$14,$H$2,FALSE)*1000000*$G$6*'MSET pivots'!L$65 -> 21981.927 | ... AH19: =VLOOKUP($C19,'MSET pivots'!$B$4:$H$14,$H$2,FALSE)*1000000*$G$6*'MSET pivots'!S$65 -> 32972.725

Sheet Final demand(3)
B2: Final demand changes (consumption, govt, etc) | H2: CVF_central | I2: =1/3 -> 0.33333333 | J2: hh
B3: Fields with * must be specified manually or filled in automatically by selecting values in other columns | H3: 3 | I3: =1/3 -> 0.33333333 | J3: gov
B5: Country | C5: Country ISO* | F5: Product | G5: Product code* | H5: Final demand category | I5: FD code* | J5: Type* | K5: Comments
B6: Italy | C6: =_xlfn.IFNA(INDEX('[1]Country list'!$A$2:$A$166,MATCH(B6,'[1]Country list'!$B$2:$B$166,0)),"") -> ITA | F6: ALL | G6: =_xlfn.IFNA(INDEX('[1]Sector list'!$A$2:$A$122,MATCH(F6,'[1]Sector list'!$B$2:$B$122,0)),"") -> ALL | H6: Household final consumption P.3h | I6: =_xlfn.IFNA(INDEX('[1]FD list'!$A$2:$A$122,MATCH(H6,'[1]FD list'!$B$2:$B$122,0)),"") -> FD_1 | J6: rel-b | K6: << Decrease final demand (HH consumption) 3% for all products in Italy
C7: ITA | F7: Pork | G7: =_xlfn.IFNA(INDEX('[1]Sector list'!$A$2:$A$122,MATCH(F7,'[1]Sector list'!$B$2:$B$122,0)),"") -> 43 | H7: ALL | I7: =_xlfn.IFNA(INDEX('[1]FD list'!$A$2:$A$122,MATCH(H7,'[1]FD list'!$B$2:$B$122,0)),"") -> ALL | J7: rel-b | K7: << Increase final demand (across all demand categories) for pork in Italy by 12% (if zero stays zero)
B8: Germany | C8: =_xlfn.IFNA(INDEX('[1]Country list'!$A$2:$A$166,MATCH(B8,'[1]Country list'!$B$2:$B$166,0)),"") -> DEU | G8: 1-23 | I8: FD_1 | J8: abs-b | K8: << Increase demand in Germany for all agricultural sectors (1-23), only for consumer demand; try NOT to use negative values as it might create issues
B9: Malawi | C9: =_xlfn.IFNA(INDEX('[1]Country list'!$A$2:$A$166,MATCH(B9,'[1]Country list'!$B$2:$B$166,0)),"") -> MWI | F9: Building construction | G9: =_xlfn.IFNA(INDEX('[1]Sector list'!$A$2:$A$122,MATCH(F9,'[1]Sector list'!$B$2:$B$122,0)),"") -> 98 | H9: Gross fixed capital formation P.51 | I9: =_xlfn.IFNA(INDEX('[1]FD list'!$A$2:$A$122,MATCH(H9,'[1]FD list'!$B$2:$B$122,0)),"") -> FD_4 | J9: rel-b | K9: << Directly decrease investment (GFCF) demand for construction sector in Malawi with 1%; NOTE: if you want to do INVESTMENT BY the sector IT SHOULD NOT BE DONE HERE
C13: REG_exp | E13: REG_imp | G13: TRAD_COMM | I13: PROD_COMM (only FD) | J13: Current options: rel-b and abs-b
B14: Start in the next line >>
B15: Producing country | C15: Producing country ISO* | D15: Consuming country | E15: Consuming country ISO* | F15: Product | G15: Product code* | H15: Final demand category | I15: FD code* | J15: Type* | K15: Comments | L15: 2019 | M15: 2020 | N15: 2021 | O15: 2022 | P15: 2023 | Q15: 2024 | R15: 2025 | S15: 2026 | T15: 2027 | U15: 2028 | V15: 2029 | W15: 2030 | X15: 2031 | Y15: 2032 | Z15: 2033 | AA15: 2034 | AB15: 2035 | AC15: 2036 | AD15: 2037 | AE15: 2038 | AF15: 2039 | AG15: 2040 | AH15: 2041 | AI15: 2042 | AJ15: 2043 | AK15: 2044 | AL15: 2045 | AM15: 2046 | AN15: 2047 | AO15: 2048 | AP15: 2049 | AQ15: 2050
C16: SEP | E16: SEP | F16: ALL | G16: ALL | H16: Household final consumption P.3h | I16: FD_1 | J16: abs-b | K16: =SUM(X16:AL16)/1000000 -> 11.046509 | X16: =VLOOKUP($C16,'MSET pivots'!$B$4:$H$14,$H$3,FALSE)*1000000*$I$2*'MSET pivots'!E$65 -> 368222.5 | Y16: =VLOOKUP($C16,'MSET pivots'!$B$4:$H$14,$H$3,FALSE)*1000000*$I2*'MSET pivots'!F$65 -> 420824.13 | Z16: =VLOOKUP($C16,'MSET pivots'!$B$4:$H$14,$H$3,FALSE)*1000000*$I2*'MSET pivots'!G$65 -> 473425.77 | AA16: =VLOOKUP($C16,'MSET pivots'!$B$4:$H$14,$H$3,FALSE)*1000000*$I2*'MSET pivots'!H$65 -> 526027.41 | AB16: =VLOOKUP($C16,'MSET pivots'!$B$4:$H$14,$H$3,FALSE)*1000000*$I2*'MSET pivots'!I$65 -> 578629.04 | AC16: =VLOOKUP($C16,'MSET pivots'!$B$4:$H$14,$H$3,FALSE)*1000000*$I2*'MSET pivots'!J$65 -> 631230.68 | AD16: =VLOOKUP($C16,'MSET pivots'!$B$4:$H$14,$H$3,FALSE)*1000000*$I2*'MSET pivots'!K$65 -> 683832.31 | AE16: =VLOOKUP($C16,'MSET pivots'!$B$4:$H$14,$H$3,FALSE)*1000000*$I2*'MSET pivots'!L$65 -> 736433.95 | AF16: =VLOOKUP($C16,'MSET pivots'!$B$4:$H$14,$H$3,FALSE)*1000000*$I2*'MSET pivots'!M$65 -> 789035.59 | ... AL16: =VLOOKUP($C16,'MSET pivots'!$B$4:$H$14,$H$3,FALSE)*1000000*$I2*'MSET pivots'!S$65 -> 1104645.4
C17: SEP | E17: SEP | F17: ALL | G17: ALL | H17: Government final consumption P.3g | I17: FD_3 | J17: abs-b | K17: =SUM(X17:AL17)/1000000 -> 11.046509 | X17: =VLOOKUP($C17,'MSET pivots'!$B$4:$H$14,$H$3,FALSE)*1000000*$I$3*'MSET pivots'!E$65 -> 368222.5 | Y17: =VLOOKUP($C17,'MSET pivots'!$B$4:$H$14,$H$3,FALSE)*1000000*$I3*'MSET pivots'!F$65 -> 420824.13 | Z17: =VLOOKUP($C17,'MSET pivots'!$B$4:$H$14,$H$3,FALSE)*1000000*$I3*'MSET pivots'!G$65 -> 473425.77 | AA17: =VLOOKUP($C17,'MSET pivots'!$B$4:$H$14,$H$3,FALSE)*1000000*$I3*'MSET pivots'!H$65 -> 526027.41 | AB17: =VLOOKUP($C17,'MSET pivots'!$B$4:$H$14,$H$3,FALSE)*1000000*$I3*'MSET pivots'!I$65 -> 578629.04 | AC17: =VLOOKUP($C17,'MSET pivots'!$B$4:$H$14,$H$3,FALSE)*1000000*$I3*'MSET pivots'!J$65 -> 631230.68 | AD17: =VLOOKUP($C17,'MSET pivots'!$B$4:$H$14,$H$3,FALSE)*1000000*$I3*'MSET pivots'!K$65 -> 683832.31 | AE17: =VLOOKUP($C17,'MSET pivots'!$B$4:$H$14,$H$3,FALSE)*1000000*$I3*'MSET pivots'!L$65 -> 736433.95 | AF17: =VLOOKUP($C17,'MSET pivots'!$B$4:$H$14,$H$3,FALSE)*1000000*$I3*'MSET pivots'!M$65 -> 789035.59 | ... AL17: =VLOOKUP($C17,'MSET pivots'!$B$4:$H$14,$H$3,FALSE)*1000000*$I3*'MSET pivots'!S$65 -> 1104645.4
C18: AFR | E18: AFR | F18: ALL | G18: ALL | H18: Household final consumption P.3h | I18: FD_1 | J18: abs-b | K18: =SUM(X18:AL18)/1000000 -> 11.495606 | X18: =VLOOKUP($C18,'MSET pivots'!$B$4:$H$14,$H$3,FALSE)*1000000*$I$2*'MSET pivots'!E$65 -> 383192.61 | Y18: =VLOOKUP($C18,'MSET pivots'!$B$4:$H$14,$H$3,FALSE)*1000000*$I$2*'MSET pivots'!F$65 -> 437932.77 | Z18: =VLOOKUP($C18,'MSET pivots'!$B$4:$H$14,$H$3,FALSE)*1000000*$I$2*'MSET pivots'!G$65 -> 492672.93 | AA18: =VLOOKUP($C18,'MSET pivots'!$B$4:$H$14,$H$3,FALSE)*1000000*$I$2*'MSET pivots'!H$65 -> 547413.09 | AB18: =VLOOKUP($C18,'MSET pivots'!$B$4:$H$14,$H$3,FALSE)*1000000*$I$2*'MSET pivots'!I$65 -> 602153.25 | AC18: =VLOOKUP($C18,'MSET pivots'!$B$4:$H$14,$H$3,FALSE)*1000000*$I$2*'MSET pivots'!J$65 -> 656893.41 | AD18: =VLOOKUP($C18,'MSET pivots'!$B$4:$H$14,$H$3,FALSE)*1000000*$I$2*'MSET pivots'!K$65 -> 711633.56 | AE18: =VLOOKUP($C18,'MSET pivots'!$B$4:$H$14,$H$3,FALSE)*1000000*$I$2*'MSET pivots'!L$65 -> 766373.72 | ... AL18: =VLOOKUP($C18,'MSET pivots'!$B$4:$H$14,$H$3,FALSE)*1000000*$I$2*'MSET pivots'!S$65 -> 1149554.8
C19: AFR | E19: AFR | F19: ALL | G19: ALL | H19: Government final consumption P.3g | I19: FD_3 | J19: abs-b | K19: =SUM(X19:AL19)/1000000 -> 11.495606 | X19: =VLOOKUP($C19,'MSET pivots'!$B$4:$H$14,$H$3,FALSE)*1000000*$I$3*'MSET pivots'!E$65 -> 383192.61 | Y19: =VLOOKUP($C19,'MSET pivots'!$B$4:$H$14,$H$3,FALSE)*1000000*$I$3*'MSET pivots'!F$65 -> 437932.77 | Z19: =VLOOKUP($C19,'MSET pivots'!$B$4:$H$14,$H$3,FALSE)*1000000*$I$3*'MSET pivots'!G$65 -> 492672.93 | AA19: =VLOOKUP($C19,'MSET pivots'!$B$4:$H$14,$H$3,FALSE)*1000000*$I$3*'MSET pivots'!H$65 -> 547413.09 | AB19: =VLOOKUP($C19,'MSET pivots'!$B$4:$H$14,$H$3,FALSE)*1000000*$I$3*'MSET pivots'!I$65 -> 602153.25 | AC19: =VLOOKUP($C19,'MSET pivots'!$B$4:$H$14,$H$3,FALSE)*1000000*$I$3*'MSET pivots'!J$65 -> 656893.41 | AD19: =VLOOKUP($C19,'MSET pivots'!$B$4:$H$14,$H$3,FALSE)*1000000*$I$3*'MSET pivots'!K$65 -> 711633.56 | AE19: =VLOOKUP($C19,'MSET pivots'!$B$4:$H$14,$H$3,FALSE)*1000000*$I$3*'MSET pivots'!L$65 -> 766373.72 | ... AL19: =VLOOKUP($C19,'MSET pivots'!$B$4:$H$14,$H$3,FALSE)*1000000*$I$3*'MSET pivots'!S$65 -> 1149554.8
C20: LAC | E20: LAC | F20: ALL | G20: ALL | H20: Household final consumption P.3h | I20: FD_1 | J20: abs-b | K20: =SUM(X20:AL20)/1000000 -> 8.5250447 | X20: =VLOOKUP($C20,'MSET pivots'!$B$4:$H$14,$H$3,FALSE)*1000000*$I$2*'MSET pivots'!E$65 -> 284172.42 | Y20: =VLOOKUP($C20,'MSET pivots'!$B$4:$H$14,$H$3,FALSE)*1000000*$I$2*'MSET pivots'!F$65 -> 324767.26 | Z20: =VLOOKUP($C20,'MSET pivots'!$B$4:$H$14,$H$3,FALSE)*1000000*$I$2*'MSET pivots'!G$65 -> 365362.11 | AA20: =VLOOKUP($C20,'MSET pivots'!$B$4:$H$14,$H$3,FALSE)*1000000*$I$2*'MSET pivots'!H$65 -> 405956.95 | AB20: =VLOOKUP($C20,'MSET pivots'!$B$4:$H$14,$H$3,FALSE)*1000000*$I$2*'MSET pivots'!I$65 -> 446551.79 | AC20: =VLOOKUP($C20,'MSET pivots'!$B$4:$H$14,$H$3,FALSE)*1000000*$I$2*'MSET pivots'!J$65 -> 487146.63 | AD20: =VLOOKUP($C20,'MSET pivots'!$B$4:$H$14,$H$3,FALSE)*1000000*$I$2*'MSET pivots'!K$65 -> 527741.47 | AE20: =VLOOKUP($C20,'MSET pivots'!$B$4:$H$14,$H$3,FALSE)*1000000*$I$2*'MSET pivots'!L$65 -> 568336.32 | ... AL20: =VLOOKUP($C20,'MSET pivots'!$B$4:$H$14,$H$3,FALSE)*1000000*$I$2*'MSET pivots'!S$65 -> 852500.21
C21: LAC | E21: LAC | F21: ALL | G21: ALL | H21: Government final consumption P.3g | I21: FD_3 | J21: abs-b | K21: =SUM(X21:AL21)/1000000 -> 8.5250447 | X21: =VLOOKUP($C21,'MSET pivots'!$B$4:$H$14,$H$3,FALSE)*1000000*$I$3*'MSET pivots'!E$65 -> 284172.42 | Y21: =VLOOKUP($C21,'MSET pivots'!$B$4:$H$14,$H$3,FALSE)*1000000*$I$3*'MSET pivots'!F$65 -> 324767.26 | Z21: =VLOOKUP($C21,'MSET pivots'!$B$4:$H$14,$H$3,FALSE)*1000000*$I$3*'MSET pivots'!G$65 -> 365362.11 | AA21: =VLOOKUP($C21,'MSET pivots'!$B$4:$H$14,$H$3,FALSE)*1000000*$I$3*'MSET pivots'!H$65 -> 405956.95 | AB21: =VLOOKUP($C21,'MSET pivots'!$B$4:$H$14,$H$3,FALSE)*1000000*$I$3*'MSET pivots'!I$65 -> 446551.79 | AC21: =VLOOKUP($C21,'MSET pivots'!$B$4:$H$14,$H$3,FALSE)*1000000*$I$3*'MSET pivots'!J$65 -> 487146.63 | AD21: =VLOOKUP($C21,'MSET pivots'!$B$4:$H$14,$H$3,FALSE)*1000000*$I$3*'MSET pivots'!K$65 -> 527741.47 | AE21: =VLOOKUP($C21,'MSET pivots'!$B$4:$H$14,$H$3,FALSE)*1000000*$I$3*'MSET pivots'!L$65 -> 568336.32 | ... AL21: =VLOOKUP($C21,'MSET pivots'!$B$4:$H$14,$H$3,FALSE)*1000000*$I$3*'MSET pivots'!S$65 -> 852500.21
B22: Pakistan | C22: SAS | E22: SAS | F22: ALL | G22: ALL | H22: Household final consumption P.3h | I22: FD_1 | J22: abs-b | K22: =SUM(X22:AL22)/1000000 -> 10.630844 | W22: ='Preliminary results'!$C$31*1000000*I2 -> 902060.73 | X22: =VLOOKUP($C22,'MSET pivots'!$B$4:$H$14,$H$3,FALSE)*1000000*$I$2*'MSET pivots'!E$65 -> 354366.77 | Y22: =VLOOKUP($C22,'MSET pivots'!$B$4:$H$14,$H$3,FALSE)*1000000*$I$2*'MSET pivots'!F$65 -> 404989.08 | Z22: =VLOOKUP($C22,'MSET pivots'!$B$4:$H$14,$H$3,FALSE)*1000000*$I$2*'MSET pivots'!G$65 -> 455611.38 | AA22: =VLOOKUP($C22,'MSET pivots'!$B$4:$H$14,$H$3,FALSE)*1000000*$I$2*'MSET pivots'!H$65 -> 506233.69 | AB22: =VLOOKUP($C22,'MSET pivots'!$B$4:$H$14,$H$3,FALSE)*1000000*$I$2*'MSET pivots'!I$65 -> 556855.99 | AC22: =VLOOKUP($C22,'MSET pivots'!$B$4:$H$14,$H$3,FALSE)*1000000*$I$2*'MSET pivots'!J$65 -> 607478.3 | AD22: =VLOOKUP($C22,'MSET pivots'!$B$4:$H$14,$H$3,FALSE)*1000000*$I$2*'MSET pivots'!K$65 -> 658100.6 | AE22: =VLOOKUP($C22,'MSET pivots'!$B$4:$H$14,$H$3,FALSE)*1000000*$I$2*'MSET pivots'!L$65 -> 708722.91 | ... AL22: =VLOOKUP($C22,'MSET pivots'!$B$4:$H$14,$H$3,FALSE)*1000000*$I$2*'MSET pivots'!S$65 -> 1063079
B23: Pakistan | C23: SAS | E23: SAS | F23: ALL | G23: ALL | H23: Government final consumption P.3g | I23: FD_3 | J23: abs-b | K23: =SUM(X23:AL23)/1000000 -> 10.630844 | W23: ='Preliminary results'!$C$31*1000000*I3 -> 902060.73 | X23: =VLOOKUP($C23,'MSET pivots'!$B$4:$H$14,$H$3,FALSE)*1000000*$I$3*'MSET pivots'!E$65 -> 354366.77 | Y23: =VLOOKUP($C23,'MSET pivots'!$B$4:$H$14,$H$3,FALSE)*1000000*$I$3*'MSET pivots'!F$65 -> 404989.08 | Z23: =VLOOKUP($C23,'MSET pivots'!$B$4:$H$14,$H$3,FALSE)*1000000*$I$3*'MSET pivots'!G$65 -> 455611.38 | AA23: =VLOOKUP($C23,'MSET pivots'!$B$4:$H$14,$H$3,FALSE)*1000000*$I$3*'MSET pivots'!H$65 -> 506233.69 | AB23: =VLOOKUP($C23,'MSET pivots'!$B$4:$H$14,$H$3,FALSE)*1000000*$I$3*'MSET pivots'!I$65 -> 556855.99 | AC23: =VLOOKUP($C23,'MSET pivots'!$B$4:$H$14,$H$3,FALSE)*1000000*$I$3*'MSET pivots'!J$65 -> 607478.3 | AD23: =VLOOKUP($C23,'MSET pivots'!$B$4:$H$14,$H$3,FALSE)*1000000*$I$3*'MSET pivots'!K$65 -> 658100.6 | AE23: =VLOOKUP($C23,'MSET pivots'!$B$4:$H$14,$H$3,FALSE)*1000000*$I$3*'MSET pivots'!L$65 -> 708722.91 | ... AL23: =VLOOKUP($C23,'MSET pivots'!$B$4:$H$14,$H$3,FALSE)*1000000*$I$3*'MSET pivots'!S$65 -> 1063079
C24: AJN | E24: AJN | F24: ALL | G24: ALL | H24: Government final consumption P.3g | I24: FD_3 | J24: rel-b | K24: =SUM(X24:AL24) -> -0.0088262816 | X24: =VLOOKUP($C24,'MSET pivots'!$J$4:$P$14,'Final demand(3)'!$H$3,FALSE)*'MSET pivots'!E$65 -> -0.0002942138 | Y24: =VLOOKUP($C24,'MSET pivots'!$J$4:$P$14,'Final demand(3)'!$H$3,FALSE)*'MSET pivots'!F$65 -> -0.00033624308 | Z24: =VLOOKUP($C24,'MSET pivots'!$J$4:$P$14,'Final demand(3)'!$H$3,FALSE)*'MSET pivots'!G$65 -> -0.00037827236 | AA24: =VLOOKUP($C24,'MSET pivots'!$J$4:$P$14,'Final demand(3)'!$H$3,FALSE)*'MSET pivots'!H$65 -> -0.00042030164 | AB24: =VLOOKUP($C24,'MSET pivots'!$J$4:$P$14,'Final demand(3)'!$H$3,FALSE)*'MSET pivots'!I$65 -> -0.00046233093 | AC24: =VLOOKUP($C24,'MSET pivots'!$J$4:$P$14,'Final demand(3)'!$H$3,FALSE)*'MSET pivots'!J$65 -> -0.00050436021 | AD24: =VLOOKUP($C24,'MSET pivots'!$J$4:$P$14,'Final demand(3)'!$H$3,FALSE)*'MSET pivots'!K$65 -> -0.00054638949 | AE24: =VLOOKUP($C24,'MSET pivots'!$J$4:$P$14,'Final demand(3)'!$H$3,FALSE)*'MSET pivots'!L$65 -> -0.00058841877 | ... AL24: =VLOOKUP($C24,'MSET pivots'!$J$4:$P$14,'Final demand(3)'!$H$3,FALSE)*'MSET pivots'!S$65 -> -0.00088262374
C25: EAS | E25: EAS | F25: ALL | G25: ALL | H25: Government final consumption P.3g | I25: FD_3 | J25: rel-b | K25: =SUM(X25:AL25) -> -0.0045455366 | X25: =VLOOKUP($C25,'MSET pivots'!$J$4:$P$14,'Final demand(3)'!$H$3,FALSE)*'MSET pivots'!E$65 -> -0.00015152016 | Y25: =VLOOKUP($C25,'MSET pivots'!$J$4:$P$14,'Final demand(3)'!$H$3,FALSE)*'MSET pivots'!F$65 -> -0.00017316525 | Z25: =VLOOKUP($C25,'MSET pivots'!$J$4:$P$14,'Final demand(3)'!$H$3,FALSE)*'MSET pivots'!G$65 -> -0.00019481033 | AA25: =VLOOKUP($C25,'MSET pivots'!$J$4:$P$14,'Final demand(3)'!$H$3,FALSE)*'MSET pivots'!H$65 -> -0.00021645542 | AB25: =VLOOKUP($C25,'MSET pivots'!$J$4:$P$14,'Final demand(3)'!$H$3,FALSE)*'MSET pivots'!I$65 -> -0.00023810051 | AC25: =VLOOKUP($C25,'MSET pivots'!$J$4:$P$14,'Final demand(3)'!$H$3,FALSE)*'MSET pivots'!J$65 -> -0.0002597456 | AD25: =VLOOKUP($C25,'MSET pivots'!$J$4:$P$14,'Final demand(3)'!$H$3,FALSE)*'MSET pivots'!K$65 -> -0.00028139069 | AE25: =VLOOKUP($C25,'MSET pivots'!$J$4:$P$14,'Final demand(3)'!$H$3,FALSE)*'MSET pivots'!L$65 -> -0.00030303577 | ... AL25: =VLOOKUP($C25,'MSET pivots'!$J$4:$P$14,'Final demand(3)'!$H$3,FALSE)*'MSET pivots'!S$65 -> -0.00045455139
C26: EEA | E26: EEA | F26: ALL | G26: ALL | H26: Government final consumption P.3g | I26: FD_3 | J26: rel-b | K26: =SUM(X26:AL26) -> -0.0094439391 | X26: =VLOOKUP($C26,'MSET pivots'!$J$4:$P$14,'Final demand(3)'!$H$3,FALSE)*'MSET pivots'!E$65 -> -0.00031480269 | Y26: =VLOOKUP($C26,'MSET pivots'!$J$4:$P$14,'Final demand(3)'!$H$3,FALSE)*'MSET pivots'!F$65 -> -0.00035977316 | Z26: =VLOOKUP($C26,'MSET pivots'!$J$4:$P$14,'Final demand(3)'!$H$3,FALSE)*'MSET pivots'!G$65 -> -0.00040474362 | AA26: =VLOOKUP($C26,'MSET pivots'!$J$4:$P$14,'Final demand(3)'!$H$3,FALSE)*'MSET pivots'!H$65 -> -0.00044971408 | AB26: =VLOOKUP($C26,'MSET pivots'!$J$4:$P$14,'Final demand(3)'!$H$3,FALSE)*'MSET pivots'!I$65 -> -0.00049468455 | AC26: =VLOOKUP($C26,'MSET pivots'!$J$4:$P$14,'Final demand(3)'!$H$3,FALSE)*'MSET pivots'!J$65 -> -0.00053965501 | AD26: =VLOOKUP($C26,'MSET pivots'!$J$4:$P$14,'Final demand(3)'!$H$3,FALSE)*'MSET pivots'!K$65 -> -0.00058462548 | AE26: =VLOOKUP($C26,'MSET pivots'!$J$4:$P$14,'Final demand(3)'!$H$3,FALSE)*'MSET pivots'!L$65 -> -0.00062959594 | ... AL26: =VLOOKUP($C26,'MSET pivots'!$J$4:$P$14,'Final demand(3)'!$H$3,FALSE)*'MSET pivots'!S$65 -> -0.00094438919
B27: United Kingdom | C27: EUR | E27: EUR | F27: ALL | G27: ALL | H27: Government final consumption P.3g | I27: FD_3 | J27: rel-b | K27: =SUM(X27:AL27) -> -0.0068766548 | W27: =('Preliminary results'!$C$31)/'Baseline govt spend'!$E$51 -> 0.00066729533 | X27: =VLOOKUP($C27,'MSET pivots'!$J$4:$P$14,'Final demand(3)'!$H$3,FALSE)*'MSET pivots'!E$65 -> -0.00022922526 | Y27: =VLOOKUP($C27,'MSET pivots'!$J$4:$P$14,'Final demand(3)'!$H$3,FALSE)*'MSET pivots'!F$65 -> -0.00026197075 | Z27: =VLOOKUP($C27,'MSET pivots'!$J$4:$P$14,'Final demand(3)'!$H$3,FALSE)*'MSET pivots'!G$65 -> -0.00029471623 | AA27: =VLOOKUP($C27,'MSET pivots'!$J$4:$P$14,'Final demand(3)'!$H$3,FALSE)*'MSET pivots'!H$65 -> -0.00032746172 | AB27: =VLOOKUP($C27,'MSET pivots'!$J$4:$P$14,'Final demand(3)'!$H$3,FALSE)*'MSET pivots'!I$65 -> -0.0003602072 | AC27: =VLOOKUP($C27,'MSET pivots'!$J$4:$P$14,'Final demand(3)'!$H$3,FALSE)*'MSET pivots'!J$65 -> -0.00039295268 | AD27: =VLOOKUP($C27,'MSET pivots'!$J$4:$P$14,'Final demand(3)'!$H$3,FALSE)*'MSET pivots'!K$65 -> -0.00042569817 | AE27: =VLOOKUP($C27,'MSET pivots'!$J$4:$P$14,'Final demand(3)'!$H$3,FALSE)*'MSET pivots'!L$65 -> -0.00045844365 | ... AL27: =VLOOKUP($C27,'MSET pivots'!$J$4:$P$14,'Final demand(3)'!$H$3,FALSE)*'MSET pivots'!S$65 -> -0.00068766204
C28: MEN | E28: MEN | F28: ALL | G28: ALL | H28: Government final consumption P.3g | I28: FD_3 | J28: rel-b | K28: =SUM(X28:AL28) -> -0.0023956582 | X28: =VLOOKUP($C28,'MSET pivots'!$J$4:$P$14,'Final demand(3)'!$H$3,FALSE)*'MSET pivots'!E$65 -> -7.9856473e-05 | Y28: =VLOOKUP($C28,'MSET pivots'!$J$4:$P$14,'Final demand(3)'!$H$3,FALSE)*'MSET pivots'!F$65 -> -9.1264198e-05 | Z28: =VLOOKUP($C28,'MSET pivots'!$J$4:$P$14,'Final demand(3)'!$H$3,FALSE)*'MSET pivots'!G$65 -> -0.00010267192 | AA28: =VLOOKUP($C28,'MSET pivots'!$J$4:$P$14,'Final demand(3)'!$H$3,FALSE)*'MSET pivots'!H$65 -> -0.00011407965 | AB28: =VLOOKUP($C28,'MSET pivots'!$J$4:$P$14,'Final demand(3)'!$H$3,FALSE)*'MSET pivots'!I$65 -> -0.00012548737 | AC28: =VLOOKUP($C28,'MSET pivots'!$J$4:$P$14,'Final demand(3)'!$H$3,FALSE)*'MSET pivots'!J$65 -> -0.0001368951 | AD28: =VLOOKUP($C28,'MSET pivots'!$J$4:$P$14,'Final demand(3)'!$H$3,FALSE)*'MSET pivots'!K$65 -> -0.00014830282 | AE28: =VLOOKUP($C28,'MSET pivots'!$J$4:$P$14,'Final demand(3)'!$H$3,FALSE)*'MSET pivots'!L$65 -> -0.00015971055 | ... AL28: =VLOOKUP($C28,'MSET pivots'!$J$4:$P$14,'Final demand(3)'!$H$3,FALSE)*'MSET pivots'!S$65 -> -0.00023956463
C29: NAM | E29: NAM | F29: ALL | G29: ALL | H29: Government final consumption P.3g | I29: FD_3 | J29: rel-b | K29: =SUM(X29:AL29) -> -0.019088338 | X29: =VLOOKUP($C29,'MSET pivots'!$J$4:$P$14,'Final demand(3)'!$H$3,FALSE)*'MSET pivots'!E$65 -> -0.00063628749 | Y29: =VLOOKUP($C29,'MSET pivots'!$J$4:$P$14,'Final demand(3)'!$H$3,FALSE)*'MSET pivots'!F$65 -> -0.00072718298 | Z29: =VLOOKUP($C29,'MSET pivots'!$J$4:$P$14,'Final demand(3)'!$H$3,FALSE)*'MSET pivots'!G$65 -> -0.00081807846 | AA29: =VLOOKUP($C29,'MSET pivots'!$J$4:$P$14,'Final demand(3)'!$H$3,FALSE)*'MSET pivots'!H$65 -> -0.00090897395 | AB29: =VLOOKUP($C29,'MSET pivots'!$J$4:$P$14,'Final demand(3)'!$H$3,FALSE)*'MSET pivots'!I$65 -> -0.00099986944 | AC29: =VLOOKUP($C29,'MSET pivots'!$J$4:$P$14,'Final demand(3)'!$H$3,FALSE)*'MSET pivots'!J$65 -> -0.0010907649 | AD29: =VLOOKUP($C29,'MSET pivots'!$J$4:$P$14,'Final demand(3)'!$H$3,FALSE)*'MSET pivots'!K$65 -> -0.0011816604 | AE29: =VLOOKUP($C29,'MSET pivots'!$J$4:$P$14,'Final demand(3)'!$H$3,FALSE)*'MSET pivots'!L$65 -> -0.0012725559 | ... AL29: =VLOOKUP($C29,'MSET pivots'!$J$4:$P$14,'Final demand(3)'!$H$3,FALSE)*'MSET pivots'!S$65 -> -0.0019088243
G42: =_xlfn.IFNA(INDEX('[1]Sector list'!$A$2:$A$122,MATCH(F42,'[1]Sector list'!$B$2:$B$122,0)),"") | I42: =_xlfn.IFNA(INDEX('[1]FD list'!$A$2:$A$122,MATCH(H42,'[1]FD list'!$B$2:$B$122,0)),"")
G43: =_xlfn.IFNA(INDEX('[1]Sector list'!$A$2:$A$122,MATCH(F43,'[1]Sector list'!$B$2:$B$122,0)),"") | I43: =_xlfn.IFNA(INDEX('[1]FD list'!$A$2:$A$122,MATCH(H43,'[1]FD list'!$B$2:$B$122,0)),"")
G44: =_xlfn.IFNA(INDEX('[1]Sector list'!$A$2:$A$122,MATCH(F44,'[1]Sector list'!$B$2:$B$122,0)),"") | I44: =_xlfn.IFNA(INDEX('[1]FD list'!$A$2:$A$122,MATCH(H44,'[1]FD list'!$B$2:$B$122,0)),"")
G45: =_xlfn.IFNA(INDEX('[1]Sector list'!$A$2:$A$122,MATCH(F45,'[1]Sector list'!$B$2:$B$122,0)),"") | I45: =_xlfn.IFNA(INDEX('[1]FD list'!$A$2:$A$122,MATCH(H45,'[1]FD list'!$B$2:$B$122,0)),"")
G46: =_xlfn.IFNA(INDEX('[1]Sector list'!$A$2:$A$122,MATCH(F46,'[1]Sector list'!$B$2:$B$122,0)),"") | I46: =_xlfn.IFNA(INDEX('[1]FD list'!$A$2:$A$122,MATCH(H46,'[1]FD list'!$B$2:$B$122,0)),"")
G47: =_xlfn.IFNA(INDEX('[1]Sector list'!$A$2:$A$122,MATCH(F47,'[1]Sector list'!$B$2:$B$122,0)),"") | I47: =_xlfn.IFNA(INDEX('[1]FD list'!$A$2:$A$122,MATCH(H47,'[1]FD list'!$B$2:$B$122,0)),"")
G48: =_xlfn.IFNA(INDEX('[1]Sector list'!$A$2:$A$122,MATCH(F48,'[1]Sector list'!$B$2:$B$122,0)),"") | I48: =_xlfn.IFNA(INDEX('[1]FD list'!$A$2:$A$122,MATCH(H48,'[1]FD list'!$B$2:$B$122,0)),"")
G49: =_xlfn.IFNA(INDEX('[1]Sector list'!$A$2:$A$122,MATCH(F49,'[1]Sector list'!$B$2:$B$122,0)),"") | I49: =_xlfn.IFNA(INDEX('[1]FD list'!$A$2:$A$122,MATCH(H49,'[1]FD list'!$B$2:$B$122,0)),"")
G50: =_xlfn.IFNA(INDEX('[1]Sector list'!$A$2:$A$122,MATCH(F50,'[1]Sector list'!$B$2:$B$122,0)),"") | I50: =_xlfn.IFNA(INDEX('[1]FD list'!$A$2:$A$122,MATCH(H50,'[1]FD list'!$B$2:$B$122,0)),"")
G51: =_xlfn.IFNA(INDEX('[1]Sector list'!$A$2:$A$122,MATCH(F51,'[1]Sector list'!$B$2:$B$122,0)),"") | I51: =_xlfn.IFNA(INDEX('[1]FD list'!$A$2:$A$122,MATCH(H51,'[1]FD list'!$B$2:$B$122,0)),"")
G52: =_xlfn.IFNA(INDEX('[1]Sector list'!$A$2:$A$122,MATCH(F52,'[1]Sector list'!$B$2:$B$122,0)),"") | I52: =_xlfn.IFNA(INDEX('[1]FD list'!$A$2:$A$122,MATCH(H52,'[1]FD list'!$B$2:$B$122,0)),"")
G53: =_xlfn.IFNA(INDEX('[1]Sector list'!$A$2:$A$122,MATCH(F53,'[1]Sector list'!$B$2:$B$122,0)),"") | I53: =_xlfn.IFNA(INDEX('[1]FD list'!$A$2:$A$122,MATCH(H53,'[1]FD list'!$B$2:$B$122,0)),"")
... G67: =_xlfn.IFNA(INDEX('[1]Sector list'!$A$2:$A$122,MATCH(F67,'[1]Sector list'!$B$2:$B$122,0)),"") | I67: =_xlfn.IFNA(INDEX('[1]FD list'!$A$2:$A$122,MATCH(H67,'[1]FD list'!$B$2:$B$122,0)),"")
I68: =_xlfn.IFNA(INDEX('[1]FD list'!$A$2:$A$122,MATCH(H68,'[1]FD list'!$B$2:$B$122,0)),"")
I69: =_xlfn.IFNA(INDEX('[1]FD list'!$A$2:$A$122,MATCH(H69,'[1]FD list'!$B$2:$B$122,0)),"")
I70: =_xlfn.IFNA(INDEX('[1]FD list'!$A$2:$A$122,MATCH(H70,'[1]FD list'!$B$2:$B$122,0)),"")
...

Sheet Investment by(3)
B2: Investment BY sector changes | G2: ='Final demand(3)'!H2 -> CVF_central | H2: ='Final demand(3)'!H3 -> 3
B3: Fields with * must be specified manually or filled in automatically by selecting values in other columns
B5: Country | C5: Country ISO* | D5: Sector investing | E5: Sector investing code* | F5: Type* | G5: Comments
G6: =1/3 -> 0.33333333 | H6: FCF
B8: Germany | C8: =_xlfn.IFNA(INDEX('[2]Country list'!$A$2:$A$166,MATCH(B8,'[2]Country list'!$B$2:$B$166,0)),"") -> DEU | E8: 1-23 | F8: abs | G8: << Increase investment in agricultural sectors in Germany, 1000 kUSD in EVERY sector
G12: relative investment is not possible, because we don’t have an investment baseline right now
C13: REG_imp | E13: PROD_COMM | G13: Current options: abs-b
B14: Start in the next line >>
B15: Country | C15: Country ISO* | D15: Sector investing | E15: Sector investing code* | F15: Type* | G15: Comments | H15: 2019 | I15: 2020 | J15: 2021 | K15: 2022 | L15: 2023 | M15: 2024 | N15: 2025 | O15: 2026 | P15: 2027 | Q15: 2028 | R15: 2029 | S15: 2030 | T15: 2031 | U15: 2032 | V15: 2033 | W15: 2034 | X15: 2035 | Y15: 2036 | Z15: 2037 | AA15: 2038 | AB15: 2039 | AC15: 2040 | AD15: 2041 | AE15: 2042 | AF15: 2043 | AG15: 2044 | AH15: 2045 | AI15: 2046 | AJ15: 2047 | AK15: 2048 | AL15: 2049 | AM15: 2050
C16: SEP | E16: ALL | F16: abs-b | G16: =SUM(T16:AH16)/1000000 -> 11.046509 | T16: =VLOOKUP($C16,'MSET pivots'!$B$4:$H$14,$H$2,FALSE)*1000000*$G$6*'MSET pivots'!E$65 -> 368222.5 | U16: =VLOOKUP($C16,'MSET pivots'!$B$4:$H$14,$H$2,FALSE)*1000000*$G$6*'MSET pivots'!F$65 -> 420824.13 | V16: =VLOOKUP($C16,'MSET pivots'!$B$4:$H$14,$H$2,FALSE)*1000000*$G$6*'MSET pivots'!G$65 -> 473425.77 | W16: =VLOOKUP($C16,'MSET pivots'!$B$4:$H$14,$H$2,FALSE)*1000000*$G$6*'MSET pivots'!H$65 -> 526027.41 | X16: =VLOOKUP($C16,'MSET pivots'!$B$4:$H$14,$H$2,FALSE)*1000000*$G$6*'MSET pivots'!I$65 -> 578629.04 | Y16: =VLOOKUP($C16,'MSET pivots'!$B$4:$H$14,$H$2,FALSE)*1000000*$G$6*'MSET pivots'!J$65 -> 631230.68 | Z16: =VLOOKUP($C16,'MSET pivots'!$B$4:$H$14,$H$2,FALSE)*1000000*$G$6*'MSET pivots'!K$65 -> 683832.31 | AA16: =VLOOKUP($C16,'MSET pivots'!$B$4:$H$14,$H$2,FALSE)*1000000*$G$6*'MSET pivots'!L$65 -> 736433.95 | ... AH16: =VLOOKUP($C16,'MSET pivots'!$B$4:$H$14,$H$2,FALSE)*1000000*$G$6*'MSET pivots'!S$65 -> 1104645.4
C17: AFR | E17: ALL | F17: abs-b | G17: =SUM(T17:AH17)/1000000 -> 11.495606 | T17: =VLOOKUP($C17,'MSET pivots'!$B$4:$H$14,$H$2,FALSE)*1000000*$G$6*'MSET pivots'!E$65 -> 383192.61 | U17: =VLOOKUP($C17,'MSET pivots'!$B$4:$H$14,$H$2,FALSE)*1000000*$G$6*'MSET pivots'!F$65 -> 437932.77 | V17: =VLOOKUP($C17,'MSET pivots'!$B$4:$H$14,$H$2,FALSE)*1000000*$G$6*'MSET pivots'!G$65 -> 492672.93 | W17: =VLOOKUP($C17,'MSET pivots'!$B$4:$H$14,$H$2,FALSE)*1000000*$G$6*'MSET pivots'!H$65 -> 547413.09 | X17: =VLOOKUP($C17,'MSET pivots'!$B$4:$H$14,$H$2,FALSE)*1000000*$G$6*'MSET pivots'!I$65 -> 602153.25 | Y17: =VLOOKUP($C17,'MSET pivots'!$B$4:$H$14,$H$2,FALSE)*1000000*$G$6*'MSET pivots'!J$65 -> 656893.41 | Z17: =VLOOKUP($C17,'MSET pivots'!$B$4:$H$14,$H$2,FALSE)*1000000*$G$6*'MSET pivots'!K$65 -> 711633.56 | AA17: =VLOOKUP($C17,'MSET pivots'!$B$4:$H$14,$H$2,FALSE)*1000000*$G$6*'MSET pivots'!L$65 -> 766373.72 | ... AH17: =VLOOKUP($C17,'MSET pivots'!$B$4:$H$14,$H$2,FALSE)*1000000*$G$6*'MSET pivots'!S$65 -> 1149554.8
C18: LAC | E18: ALL | F18: abs-b | G18: =SUM(T18:AH18)/1000000 -> 8.5250447 | T18: =VLOOKUP($C18,'MSET pivots'!$B$4:$H$14,$H$2,FALSE)*1000000*$G$6*'MSET pivots'!E$65 -> 284172.42 | U18: =VLOOKUP($C18,'MSET pivots'!$B$4:$H$14,$H$2,FALSE)*1000000*$G$6*'MSET pivots'!F$65 -> 324767.26 | V18: =VLOOKUP($C18,'MSET pivots'!$B$4:$H$14,$H$2,FALSE)*1000000*$G$6*'MSET pivots'!G$65 -> 365362.11 | W18: =VLOOKUP($C18,'MSET pivots'!$B$4:$H$14,$H$2,FALSE)*1000000*$G$6*'MSET pivots'!H$65 -> 405956.95 | X18: =VLOOKUP($C18,'MSET pivots'!$B$4:$H$14,$H$2,FALSE)*1000000*$G$6*'MSET pivots'!I$65 -> 446551.79 | Y18: =VLOOKUP($C18,'MSET pivots'!$B$4:$H$14,$H$2,FALSE)*1000000*$G$6*'MSET pivots'!J$65 -> 487146.63 | Z18: =VLOOKUP($C18,'MSET pivots'!$B$4:$H$14,$H$2,FALSE)*1000000*$G$6*'MSET pivots'!K$65 -> 527741.47 | AA18: =VLOOKUP($C18,'MSET pivots'!$B$4:$H$14,$H$2,FALSE)*1000000*$G$6*'MSET pivots'!L$65 -> 568336.32 | ... AH18: =VLOOKUP($C18,'MSET pivots'!$B$4:$H$14,$H$2,FALSE)*1000000*$G$6*'MSET pivots'!S$65 -> 852500.21
C19: SAS | E19: ALL | F19: abs-b | G19: =SUM(T19:AH19)/1000000 -> 10.630844 | S19: ='Preliminary results'!$C$31*1000000*G6 -> 902060.73 | T19: =VLOOKUP($C19,'MSET pivots'!$B$4:$H$14,$H$2,FALSE)*1000000*$G$6*'MSET pivots'!E$65 -> 354366.77 | U19: =VLOOKUP($C19,'MSET pivots'!$B$4:$H$14,$H$2,FALSE)*1000000*$G$6*'MSET pivots'!F$65 -> 404989.08 | V19: =VLOOKUP($C19,'MSET pivots'!$B$4:$H$14,$H$2,FALSE)*1000000*$G$6*'MSET pivots'!G$65 -> 455611.38 | W19: =VLOOKUP($C19,'MSET pivots'!$B$4:$H$14,$H$2,FALSE)*1000000*$G$6*'MSET pivots'!H$65 -> 506233.69 | X19: =VLOOKUP($C19,'MSET pivots'!$B$4:$H$14,$H$2,FALSE)*1000000*$G$6*'MSET pivots'!I$65 -> 556855.99 | Y19: =VLOOKUP($C19,'MSET pivots'!$B$4:$H$14,$H$2,FALSE)*1000000*$G$6*'MSET pivots'!J$65 -> 607478.3 | Z19: =VLOOKUP($C19,'MSET pivots'!$B$4:$H$14,$H$2,FALSE)*1000000*$G$6*'MSET pivots'!K$65 -> 658100.6 | AA19: =VLOOKUP($C19,'MSET pivots'!$B$4:$H$14,$H$2,FALSE)*1000000*$G$6*'MSET pivots'!L$65 -> 708722.91 | ... AH19: =VLOOKUP($C19,'MSET pivots'!$B$4:$H$14,$H$2,FALSE)*1000000*$G$6*'MSET pivots'!S$65 -> 1063079

Sheet Final demand(4)
B2: Final demand changes (consumption, govt, etc) | H2: CVF_upper | I2: =1/3 -> 0.33333333 | J2: hh
B3: Fields with * must be specified manually or filled in automatically by selecting values in other columns | H3: 4 | I3: =1/3 -> 0.33333333 | J3: gov
B5: Country | C5: Country ISO* | F5: Product | G5: Product code* | H5: Final demand category | I5: FD code* | J5: Type* | K5: Comments
B6: Italy | C6: =_xlfn.IFNA(INDEX('[1]Country list'!$A$2:$A$166,MATCH(B6,'[1]Country list'!$B$2:$B$166,0)),"") -> ITA | F6: ALL | G6: =_xlfn.IFNA(INDEX('[1]Sector list'!$A$2:$A$122,MATCH(F6,'[1]Sector list'!$B$2:$B$122,0)),"") -> ALL | H6: Household final consumption P.3h | I6: =_xlfn.IFNA(INDEX('[1]FD list'!$A$2:$A$122,MATCH(H6,'[1]FD list'!$B$2:$B$122,0)),"") -> FD_1 | J6: rel-b | K6: << Decrease final demand (HH consumption) 3% for all products in Italy
C7: ITA | F7: Pork | G7: =_xlfn.IFNA(INDEX('[1]Sector list'!$A$2:$A$122,MATCH(F7,'[1]Sector list'!$B$2:$B$122,0)),"") -> 43 | H7: ALL | I7: =_xlfn.IFNA(INDEX('[1]FD list'!$A$2:$A$122,MATCH(H7,'[1]FD list'!$B$2:$B$122,0)),"") -> ALL | J7: rel-b | K7: << Increase final demand (across all demand categories) for pork in Italy by 12% (if zero stays zero)
B8: Germany | C8: =_xlfn.IFNA(INDEX('[1]Country list'!$A$2:$A$166,MATCH(B8,'[1]Country list'!$B$2:$B$166,0)),"") -> DEU | G8: 1-23 | I8: FD_1 | J8: abs-b | K8: << Increase demand in Germany for all agricultural sectors (1-23), only for consumer demand; try NOT to use negative values as it might create issues
B9: Malawi | C9: =_xlfn.IFNA(INDEX('[1]Country list'!$A$2:$A$166,MATCH(B9,'[1]Country list'!$B$2:$B$166,0)),"") -> MWI | F9: Building construction | G9: =_xlfn.IFNA(INDEX('[1]Sector list'!$A$2:$A$122,MATCH(F9,'[1]Sector list'!$B$2:$B$122,0)),"") -> 98 | H9: Gross fixed capital formation P.51 | I9: =_xlfn.IFNA(INDEX('[1]FD list'!$A$2:$A$122,MATCH(H9,'[1]FD list'!$B$2:$B$122,0)),"") -> FD_4 | J9: rel-b | K9: << Directly decrease investment (GFCF) demand for construction sector in Malawi with 1%; NOTE: if you want to do INVESTMENT BY the sector IT SHOULD NOT BE DONE HERE
C13: REG_exp | E13: REG_imp | G13: TRAD_COMM | I13: PROD_COMM (only FD) | J13: Current options: rel-b and abs-b
B14: Start in the next line >>
B15: Producing country | C15: Producing country ISO* | D15: Consuming country | E15: Consuming country ISO* | F15: Product | G15: Product code* | H15: Final demand category | I15: FD code* | J15: Type* | K15: Comments | L15: 2019 | M15: 2020 | N15: 2021 | O15: 2022 | P15: 2023 | Q15: 2024 | R15: 2025 | S15: 2026 | T15: 2027 | U15: 2028 | V15: 2029 | W15: 2030 | X15: 2031 | Y15: 2032 | Z15: 2033 | AA15: 2034 | AB15: 2035 | AC15: 2036 | AD15: 2037 | AE15: 2038 | AF15: 2039 | AG15: 2040 | AH15: 2041 | AI15: 2042 | AJ15: 2043 | AK15: 2044 | AL15: 2045 | AM15: 2046 | AN15: 2047 | AO15: 2048 | AP15: 2049 | AQ15: 2050
C16: SEP | E16: SEP | F16: ALL | G16: ALL | H16: Household final consumption P.3h | I16: FD_1 | J16: abs-b | K16: =SUM(X16:AL16)/1000000 -> 46.609068 | X16: =VLOOKUP($C16,'MSET pivots'!$B$4:$H$14,$H$3,FALSE)*1000000*$I$2*'MSET pivots'!E$65 -> 1553658.9 | Y16: =VLOOKUP($C16,'MSET pivots'!$B$4:$H$14,$H$3,FALSE)*1000000*$I2*'MSET pivots'!F$65 -> 1775603.5 | Z16: =VLOOKUP($C16,'MSET pivots'!$B$4:$H$14,$H$3,FALSE)*1000000*$I2*'MSET pivots'!G$65 -> 1997548.1 | AA16: =VLOOKUP($C16,'MSET pivots'!$B$4:$H$14,$H$3,FALSE)*1000000*$I2*'MSET pivots'!H$65 -> 2219492.7 | AB16: =VLOOKUP($C16,'MSET pivots'!$B$4:$H$14,$H$3,FALSE)*1000000*$I2*'MSET pivots'!I$65 -> 2441437.4 | AC16: =VLOOKUP($C16,'MSET pivots'!$B$4:$H$14,$H$3,FALSE)*1000000*$I2*'MSET pivots'!J$65 -> 2663382 | AD16: =VLOOKUP($C16,'MSET pivots'!$B$4:$H$14,$H$3,FALSE)*1000000*$I2*'MSET pivots'!K$65 -> 2885326.6 | AE16: =VLOOKUP($C16,'MSET pivots'!$B$4:$H$14,$H$3,FALSE)*1000000*$I2*'MSET pivots'!L$65 -> 3107271.2 | AF16: =VLOOKUP($C16,'MSET pivots'!$B$4:$H$14,$H$3,FALSE)*1000000*$I2*'MSET pivots'!M$65 -> 3329215.8 | ... AL16: =VLOOKUP($C16,'MSET pivots'!$B$4:$H$14,$H$3,FALSE)*1000000*$I2*'MSET pivots'!S$65 -> 4660883.5
